yr.exception.YRInvokeError
==============================

.. py:exception:: exception yr.exception.YRInvokeError(cause, traceback_str: str)

    表示在调用期间发生的错误。